<?xml version="1.0" ?>
<sdf version="1.5">
  <model name="robo_holly">  
  <static>false</static>

  <!-- ****************** ROBOT BASE FOOTPRINT ***************************  -->
  <pose>0.0 0.0 0.0 0.0 0.0 0.0</pose>
  <link name="base_footprint"/>

  <!-- ********************** ROBOT BASE *********************************  -->
  <link name="base_link">

    <collision name="base_collision">
      <pose>0 0 0.0 0 0 0</pose>
      <geometry>
        <box>
          <size>0.4318 0.36195 0.0508</size>
        </box>
      </geometry>
    </collision>

    <visual name="base_visual">
      <pose>0 0 -0.05 0 0 3.141592654</pose>
      <geometry>
        <box>
          <size>0.4318 0.36195 0.0508</size>
        </box>
      </geometry>
      <material>
        <ambient>1.0 0.0 0.0 1.0</ambient>
        <diffuse>1.0 0.0 0.0 1.0</diffuse>
        <specular>0.0 0.0 0.0 1.0</specular>
        <emissive>0.0 0.0 0.0 1.0</emissive>
      </material>
    </visual>
  </link>

  <!-- *********************** IMU SENSOR SETUP **************************  -->
  <link name="imu_link">
    <gravity>true</gravity>
    <sensor name="bmb_imu" type="imu">
      <always_on>true</always_on>
      <update_rate>100</update_rate>
      <visualize>true</visualize>
      <imu>
        <orientation>
          <x>
            <noise type="gaussian">
              <mean>0.0</mean>
              <stddev>2e-3</stddev>
            </noise>
          </x>
          <y>
            <noise type="gaussian">
              <mean>0.0</mean>
              <stddev>2e-3</stddev>
            </noise>
          </y>
          <z>
            <noise type="gaussian">
              <mean>0.0</mean>
              <stddev>2e-3</stddev>
            </noise>
          </z>
        </orientation>
        <angular_velocity>
          <x>
            <noise type="gaussian">
              <mean>0.0</mean>
              <stddev>2e-4</stddev>
            </noise>
          </x>
          <y>
            <noise type="gaussian">
              <mean>0.0</mean>
              <stddev>2e-4</stddev>
            </noise>
          </y>
          <z>
            <noise type="gaussian">
              <mean>0.0</mean>
              <stddev>2e-4</stddev>
            </noise>
          </z>
        </angular_velocity>
        <linear_acceleration>
          <x>
            <noise type="gaussian">
              <mean>0.0</mean>
              <stddev>1.7e-2</stddev>
            </noise>
          </x>
          <y>
            <noise type="gaussian">
              <mean>0.0</mean>
              <stddev>1.7e-2</stddev>
            </noise>
          </y>
          <z>
            <noise type="gaussian">
              <mean>0.0</mean>
              <stddev>1.7e-2</stddev>
            </noise>
          </z>
        </linear_acceleration>
      </imu>
      <plugin name="basic_mobile_bot_imu" filename="libgazebo_ros_imu_sensor.so">
        <initial_orientation_as_reference>false</initial_orientation_as_reference>
        <frame_name>imu_link</frame_name>
        <ros>
          <namespace>/imu</namespace>
          <remapping>~/out:=data</remapping>
        </ros>
      </plugin>
    </sensor>
  </link>

  <!-- *********************** GPS SETUP *********************************  -->
  <link name="gps_link">
    <sensor name="bmb_gps" type="gps">
      <always_on>true</always_on>
      <update_rate>10.0</update_rate>
      <gps>
        <position_sensing>
          <horizontal>
            <noise type="gaussian">
              <mean>0.0</mean>
              <stddev>1e-2</stddev>
            </noise>
          </horizontal>
          <vertical>
            <noise type="gaussian">
              <mean>0.0</mean>
              <stddev>1</stddev>
            </noise>
          </vertical>
        </position_sensing>
      </gps>
      <plugin name="basic_mobile_bot_gps" filename="libgazebo_ros_gps_sensor.so">
        <ros>
          <remapping>~/out:=gps/fix</remapping>
        </ros>
      </plugin>
    </sensor>
  </link>

  <!-- ****************************** LIDAR *****************************    -->
  <link name="lidar_link">    
    <inertial>
      <pose>0 0 -0.01 0 0 0</pose>
      <inertia>
        <ixx>0.001</ixx>
        <ixy>0.000</ixy>
        <ixz>0.000</ixz>
        <iyy>0.001</iyy>
        <iyz>0.000</iyz>
        <izz>0.001</izz>
      </inertia>
      <mass>0.114</mass>
    </inertial>

    <collision name="lidar_collision">
      <pose>0 0 0.01 0 0 0</pose>
      <geometry>
        <cylinder>
          <radius>0.0381</radius>
          <length>0.057</length>
        </cylinder>
      </geometry>
    </collision>

    <visual name="lidar_visual">
      <pose>0 0 -0.01 0 0 0</pose>
      <geometry>
        <cylinder>
          <radius>0.0381</radius>
          <length>0.057</length>
        </cylinder>
      </geometry>
      <material>
        <ambient>0.0 0.0 0.0 1.0</ambient>
        <diffuse>0.0 0.0 0.0 1.0</diffuse>
        <specular>0.0 0.0 0.0 1.0</specular>
        <emissive>0.0 0.0 0.0 1.0</emissive>
      </material>
    </visual>

    <sensor name="lidar" type="ray">
      <pose>0 0 -0.01 0 0 0</pose>
      <always_on>true</always_on>
      <visualize>true</visualize>
      <update_rate>5</update_rate>
      <ray>
        <scan>
          <horizontal>
            <samples>120</samples>
            <resolution>1.000000</resolution>
            <min_angle>-3.14159</min_angle>
            <max_angle>3.14159</max_angle>
          </horizontal>
        </scan>
        <range>
          <min>0.3</min>
          <max>15.0</max>
          <resolution>0.015</resolution>
        </range>
        <noise>
          <type>gaussian</type>
          <mean>0.0</mean>
          <stddev>0.01</stddev>
        </noise>
      </ray>
      <plugin name="scan" filename="libgazebo_ros_ray_sensor.so">
        <ros>
          <remapping>~/out:=scan</remapping>
        </ros>
        <output_type>sensor_msgs/LaserScan</output_type>
        <frame_name>lidar_link</frame_name>
      </plugin>
    </sensor>
  </link>
  
  <!-- *********************** DRIVE WHEELS ******************************  -->
  <link name="drivewhl_lf_link">
    <pose>-0.1651 0.194 -0.05 0 1.570796 1.570796</pose>
    
    <collision name="drivewhl_lf_collision">
      <geometry>
        <cylinder>
          <radius>0.0508</radius>
          <length>0.0381</length>
        </cylinder>
      </geometry>
    </collision>

    <visual name="drivewhl_lf_visual">
      <geometry>
        <cylinder>
          <radius>0.0508</radius>
          <length>0.0381</length>
        </cylinder>
      </geometry>
    </visual>
  </link>

  <link name="drivewhl_rf_link">
    <pose>-0.1651 -0.194 -0.05 0 1.570796 1.570796</pose>
    
    <collision name="drivewhl_rf_collision">
      <geometry>
        <cylinder>
          <radius>0.0508</radius>
          <length>0.0381</length>
        </cylinder>
      </geometry>
    </collision>

    <visual name="drivewhl_rf_visual">
      <geometry>
        <cylinder>
          <radius>0.0508</radius>
          <length>0.0381</length>
        </cylinder>
      </geometry>
    </visual>
  </link>

  <link name="drivewhl_lb_link">
    <pose>0.1651 0.194 -0.05 0 1.570796 1.570796</pose>
    
    <collision name="drivewhl_lb_collision">
      <geometry>
        <cylinder>
          <radius>0.0508</radius>
          <length>0.0381</length>
        </cylinder>
      </geometry>
    </collision>

    <visual name="drivewhl_lb_visual">
      <geometry>
        <cylinder>
          <radius>0.0508</radius>
          <length>0.0381</length>
        </cylinder>
      </geometry>
    </visual>
  </link>

  <link name="drivewhl_rb_link">
    <pose>0.1651 -0.194 -0.05 0 1.570796 1.570796</pose>
    
    <collision name="drivewhl_rb_collision">
      <geometry>
        <cylinder>
          <radius>0.0508</radius>
          <length>0.0381</length>
        </cylinder>
      </geometry>
    </collision>

    <visual name="drivewhl_rb_visual">
      <geometry>
        <cylinder>
          <radius>0.0508</radius>
          <length>0.0381</length>
        </cylinder>
      </geometry>
    </visual>
  </link>

  <!-- ************************ JOINTS ***********************************  -->
  <!-- Pose of the joint is the same as the child link frame -->
  <!-- Axis is the axis of rotation relative to the child link frame -->
  
  <joint name="base_joint" type="fixed">
    <parent>base_footprint</parent>
    <child>base_link</child>
    <pose>0 0 0 0 0 0</pose>
  </joint>

  <joint name="drivewhl_lf_joint" type="revolute">
    <parent>base_link</parent>
    <child>drivewhl_lf_link</child>
    <pose>0 0 0 0 0 0</pose>
    <axis>
      <xyz>0 0 1</xyz>
    </axis>
  </joint>

  <joint name="drivewhl_rf_joint" type="revolute">
    <parent>base_link</parent>
    <child>drivewhl_rf_link</child>
    <pose>0 0 0 0 0 0</pose>
    <axis>
      <xyz>0 0 1</xyz>
    </axis>
  </joint>

  <joint name="drivewhl_lb_joint" type="revolute">
    <parent>base_link</parent>
    <child>drivewhl_lb_link</child>
    <pose>0 0 0 0 0 0</pose>
    <axis>
      <xyz>0 0 1</xyz>
    </axis>
  </joint>

  <joint name="drivewhl_rb_joint" type="revolute">
    <parent>base_link</parent>
    <child>drivewhl_rb_link</child>
    <pose>0 0 0 0 0 0</pose>
    <axis>
      <xyz>0 0 1</xyz>
    </axis>
  </joint>

  <joint name="imu_joint" type="fixed">
    <parent>base_link</parent>
    <child>imu_link</child>
    <pose>0 0 0 0 0 0</pose>
  </joint>  

  <joint name="gps_joint" type="fixed">
    <parent>base_link</parent>
    <child>gps_link</child>
    <pose>0 0 0 0 0 0</pose>
  </joint>  
  
  <joint name="lidar_joint" type="fixed">
    <parent>base_link</parent>
    <child>lidar_link</child>
    <pose>0 0 0 0 0 0</pose>
  </joint>

 <!-- *********************** WHEEL ODOMETRY ***************************    -->

  <plugin name="object_controller" filename="libgazebo_ros_planar_move.so">
      <commandTopic>cmd_vel</commandTopic>
      <odometryTopic>odom</odometryTopic>
      <odometryFrame>odom</odometryFrame>
      <odometryRate>20.0</odometryRate>
      <robotBaseFrame>base_footprint</robotBaseFrame>
  </plugin>

 <!-- *********************** JOINT STATE PUBLISHER *********************   -->
  
  <plugin name="basic_mobile_bot_joint_state" filename="libgazebo_ros_joint_state_publisher.so">
    <ros>
      <remapping>~/out:=joint_states</remapping>
    </ros>
    <update_rate>30</update_rate>
    <joint_name>drivewhl_lf_joint</joint_name>
    <joint_name>drivewhl_rf_joint</joint_name>
    <joint_name>drivewhl_lb_joint</joint_name>
    <joint_name>drivewhl_rb_joint</joint_name>
  </plugin>   
  
  </model>
</sdf>